Workbook
Name _16_09_2024: #REF!
Name Campaign: Posts!$M$2:$M$301
Name Click_through_rate: Posts!#REF!
Name Clicks: Posts!$J$2:$J$301
Name Comments: Posts!$I$2:$I$301
Name ContentType: Posts!$D$2:$D$301
Name Date: Posts!$C$2:$C$301
Name Engagement_Rate: Posts!$N$2:$N$301
Name Hashtag: #REF!
Name Hashtags.1: Posts!$E$2:$E$301
Name Hashtags.2: Posts!$F$2:$F$301
Name Impressions: Posts!$L$2:$L$301
Name Likes: Posts!$G$2:$G$301
Name Performance: Posts!#REF!
Name Platform: Posts!$B$2:$B$301
Name PostID: Posts!$A$2:$A$301
Name Reach: Posts!$K$2:$K$301
Name Shares: Posts!$H$2:$H$301
Name YouTube: #REF!

Sheet Posts
A1: PostID | B1: Platform | C1: Date | D1: ContentType | E1: Hashtags.1 | F1: Hashtags.2 | G1: Likes | H1: Shares | I1: Comments | J1: Clicks | K1: Reach | L1: Impressions | M1: Campaign | N1: Engagement Rate | O1: Click through rate | P1: performance
A2: A1 | B2: YouTube | C2: 45649 | D2: Image | E2: #AppleWatchUltra2 | F2: #HealthTech | G2: 24516 | H2: 976 | I2: 974 | J2: 2675 | K2: 23275 | L2: 202932 | M2: Apple Watch Ultra 2 Launch | N2: =(G2+H2+I2)/L2 -> 0.13041807 | O2: =Table2[[#This Row],[Shares]]/Table2[[#This Row],[Impressions]] -> 0.0048094928 | P2: =(Table2[[#This Row],[Engagement Rate]]+Table2[[#This Row],[Click through rate]])*100 -> 13.522756
A3: A2 | B3: LinkedIn | C3: 45903 | D3: Image | E3: #MacBookAirM3 | F3: #AppleInnovation | G3: 4779 | H3: 1110 | I3: 436 | J3: 1574 | K3: 77167 | L3: 71585 | M3: Apple Event September 2025 | N3: =(G3+H3+I3)/L3 -> 0.088356499 | O3: =Table2[[#This Row],[Shares]]/Table2[[#This Row],[Impressions]] -> 0.015506042 | P3: =(Table2[[#This Row],[Engagement Rate]]+Table2[[#This Row],[Click through rate]])*100 -> 10.386254
A4: A3 | B4: Instagram | C4: 45789 | D4: Tweet | E4: #AppleDesign | F4: #Innovation | G4: 19308 | H4: 1318 | I4: 795 | J4: 1499 | K4: 52307 | L4: 193087 | M4: Sustainability Awareness Drive | N4: =(G4+H4+I4)/L4 -> 0.11093963 | O4: =Table2[[#This Row],[Shares]]/Table2[[#This Row],[Impressions]] -> 0.0068259386 | P4: =(Table2[[#This Row],[Engagement Rate]]+Table2[[#This Row],[Click through rate]])*100 -> 11.776557
A5: A4 | B5: YouTube | C5: 45516 | D5: Video | E5: #AppleEvent | F5: #iPadPro | G5: 3581 | H5: 517 | I5: 880 | J5: 1925 | K5: 18636 | L5: 248611 | M5: iPhone 16 Launch | N5: =(G5+H5+I5)/L5 -> 0.020023249 | O5: =Table2[[#This Row],[Shares]]/Table2[[#This Row],[Impressions]] -> 0.002079554 | P5: =(Table2[[#This Row],[Engagement Rate]]+Table2[[#This Row],[Click through rate]])*100 -> 2.2102803
A6: A5 | B6: YouTube | C6: 45904 | D6: Video | E6: #AppleWatchUltra2 | F6: #HealthTech | G6: 21708 | H6: 435 | I6: 317 | J6: 1213 | K6: 70701 | L6: 83585 | M6: Apple Event September 2025 | N6: =(G6+H6+I6)/L6 -> 0.2687085 | O6: =Table2[[#This Row],[Shares]]/Table2[[#This Row],[Impressions]] -> 0.0052042831 | P6: =(Table2[[#This Row],[Engagement Rate]]+Table2[[#This Row],[Click through rate]])*100 -> 27.391278
A7: A6 | B7: LinkedIn | C7: 45905 | D7: Image | E7: #ShotOniPhone | G7: 14677 | H7: 533 | I7: 759 | J7: 753 | K7: 23275 | L7: 66958 | M7: Apple Event September 2025 | N7: =(G7+H7+I7)/L7 -> 0.23849279 | O7: =Table2[[#This Row],[Shares]]/Table2[[#This Row],[Impressions]] -> 0.0079602139 | P7: =(Table2[[#This Row],[Engagement Rate]]+Table2[[#This Row],[Click through rate]])*100 -> 24.6453
A8: A7 | B8: Instagram | C8: 45467 | D8: Carousel | E8: #AppleMusic | F8: #AppleLifestyle | G8: 7713 | H8: 575 | I8: 417 | J8: 336 | K8: 61660 | L8: 66017 | M8: iPhone 16 Launch | N8: =(G8+H8+I8)/L8 -> 0.13185998 | O8: =Table2[[#This Row],[Shares]]/Table2[[#This Row],[Impressions]] -> 0.0087098778 | P8: =(Table2[[#This Row],[Engagement Rate]]+Table2[[#This Row],[Click through rate]])*100 -> 14.056985
A9: A8 | B9: Instagram | C9: 45486 | D9: Video | E9: #AppleWatch | F9: #Health | G9: 18639 | H9: 1360 | I9: 898 | J9: 2011 | K9: 42841 | L9: 247779 | M9: iPhone 16 Launch | N9: =(G9+H9+I9)/L9 -> 0.084337252 | O9: =Table2[[#This Row],[Shares]]/Table2[[#This Row],[Impressions]] -> 0.0054887622 | P9: =(Table2[[#This Row],[Engagement Rate]]+Table2[[#This Row],[Click through rate]])*100 -> 8.9826014
A10: A9 | B10: YouTube | C10: 45534 | D10: Carousel | E10: #MacBookAirM3 | F10: #AppleInnovation | G10: 6804 | H10: 787 | I10: 970 | J10: 1095 | K10: 56343 | L10: 164677 | M10: Apple Watch Ultra 2 Launch | N10: =(G10+H10+I10)/L10 -> 0.051986616 | O10: =Table2[[#This Row],[Shares]]/Table2[[#This Row],[Impressions]] -> 0.0047790523 | P10: =(Table2[[#This Row],[Engagement Rate]]+Table2[[#This Row],[Click through rate]])*100 -> 5.6765669
A11: A10 | B11: Twitter | C11: 45727 | D11: Video | E11: #iPhone16Launch | F11: #AppleEvent | G11: 20222 | H11: 712 | I11: 604 | J11: 1272 | K11: 71598 | L11: 216422 | M11: Sustainability Awareness Drive | N11: =(G11+H11+I11)/L11 -> 0.099518533 | O11: =Table2[[#This Row],[Shares]]/Table2[[#This Row],[Impressions]] -> 0.0032898689 | P11: =(Table2[[#This Row],[Engagement Rate]]+Table2[[#This Row],[Click through rate]])*100 -> 10.28084
A12: A11 | B12: YouTube | C12: 45690 | D12: Carousel | E12: #AppleEvent | F12: #iPadPro | G12: 12136 | H12: 1117 | I12: 834 | J12: 892 | K12: 24675 | L12: 183273 | M12: Sustainability Awareness Drive | N12: =(G12+H12+I12)/L12 -> 0.076863477 | O12: =Table2[[#This Row],[Shares]]/Table2[[#This Row],[Impressions]] -> 0.006094733 | P12: =(Table2[[#This Row],[Engagement Rate]]+Table2[[#This Row],[Click through rate]])*100 -> 8.295821
A13: A12 | B13: YouTube | C13: 45494 | D13: Tweet | E13: #MacBookAirM3 | F13: #AppleInnovation | G13: 2009 | H13: 1072 | I13: 550 | J13: 1437 | K13: 22982 | L13: 69426 | M13: iPhone 16 Launch | N13: =(G13+H13+I13)/L13 -> 0.052300291 | O13: =Table2[[#This Row],[Shares]]/Table2[[#This Row],[Impressions]] -> 0.015440901 | P13: =(Table2[[#This Row],[Engagement Rate]]+Table2[[#This Row],[Click through rate]])*100 -> 6.7741192
A14: A13 | B14: YouTube | C14: 45614 | D14: Carousel | E14: #AppleMusic | F14: #AppleLifestyle | G14: 21255 | H14: 1452 | I14: 625 | J14: 1624 | K14: 21282 | L14: 57778 | M14: MacBook Air M3 Campaign | N14: =(G14+H14+I14)/L14 -> 0.40382152 | O14: =Table2[[#This Row],[Shares]]/Table2[[#This Row],[Impressions]] -> 0.025130673 | P14: =(Table2[[#This Row],[Engagement Rate]]+Table2[[#This Row],[Click through rate]])*100 -> 42.89522
A15: A14 | B15: YouTube | C15: 45906 | D15: Tweet | E15: #AppleWatch | F15: #Health | G15: 7124 | H15: 469 | I15: 851 | J15: 2571 | K15: 33802 | L15: 216313 | M15: Apple Event September 2025 | N15: =(G15+H15+I15)/L15 -> 0.039036026 | O15: =Table2[[#This Row],[Shares]]/Table2[[#This Row],[Impressions]] -> 0.0021681545 | P15: =(Table2[[#This Row],[Engagement Rate]]+Table2[[#This Row],[Click through rate]])*100 -> 4.1204181
A16: A15 | B16: LinkedIn | C16: 45907 | D16: Tweet | E16: #AppleDesign | F16: #Innovation | G16: 3015 | H16: 997 | I16: 783 | J16: 617 | K16: 77167 | L16: 82229 | M16: Apple Event September 2025 | N16: =(G16+H16+I16)/L16 -> 0.058312761 | O16: =Table2[[#This Row],[Shares]]/Table2[[#This Row],[Impressions]] -> 0.012124676 | P16: =(Table2[[#This Row],[Engagement Rate]]+Table2[[#This Row],[Click through rate]])*100 -> 7.0437437
A17: A16 | B17: Instagram | C17: 45530 | D17: Carousel | E17: #AppleWatch | F17: #Health | G17: 4193 | H17: 924 | I17: 707 | J17: 2696 | K17: 55075 | L17: 126652 | M17: iPhone 16 Launch | N17: =(G17+H17+I17)/L17 -> 0.045984272 | O17: =Table2[[#This Row],[Shares]]/Table2[[#This Row],[Impressions]] -> 0.0072955816 | P17: =(Table2[[#This Row],[Engagement Rate]]+Table2[[#This Row],[Click through rate]])*100 -> 5.3279853
A18: A17 | B18: LinkedIn | C18: 45782 | D18: Tweet | E18: #AppleEvent | F18: #iPhone16 | G18: 10415 | H18: 1388 | I18: 725 | J18: 2462 | K18: 53082 | L18: 168267 | M18: MacBook Air M3 Campaign | N18: =(G18+H18+I18)/L18 -> 0.074453101 | O18: =Table2[[#This Row],[Shares]]/Table2[[#This Row],[Impressions]] -> 0.0082487951 | P18: =(Table2[[#This Row],[Engagement Rate]]+Table2[[#This Row],[Click through rate]])*100 -> 8.2701896
A19: A18 | B19: LinkedIn | C19: 45523 | D19: Image | E19: #AppleWatch | F19: #Health | G19: 15550 | H19: 204 | I19: 279 | J19: 1646 | K19: 35819 | L19: 219436 | M19: Apple Watch Ultra 2 Launch | N19: =(G19+H19+I19)/L19 -> 0.073064584 | O19: =Table2[[#This Row],[Shares]]/Table2[[#This Row],[Impressions]] -> 0.00092965603 | P19: =(Table2[[#This Row],[Engagement Rate]]+Table2[[#This Row],[Click through rate]])*100 -> 7.399424
... A28: A27 | B28: Twitter | C28: 45552 | D28: Tweet | E28: #iPhone16Launch | F28: #AppleEvent | G28: 20017 | H28: 495 | I28: 178 | J28: 2683 | K28: 32244 | L28: 182633 | M28: Apple Watch Ultra 2 Launch | N28: =(G28+H28+I28)/L28 -> 0.1132873 | O28: =Table2[[#This Row],[Shares]]/Table2[[#This Row],[Impressions]] -> 0.0027103536 | P28: =(Table2[[#This Row],[Engagement Rate]]+Table2[[#This Row],[Click through rate]])*100 -> 11.599766
A29: A28 | B29: Twitter | C29: 45720 | D29: Tweet | E29: #ShotOniPhone | G29: 12344 | H29: 815 | I29: 298 | J29: 2439 | K29: 6259 | L29: 237133 | M29: iPhone 16 Launch | N29: =(G29+H29+I29)/L29 -> 0.056748744 | O29: =Table2[[#This Row],[Shares]]/Table2[[#This Row],[Impressions]] -> 0.0034368898 | P29: =(Table2[[#This Row],[Engagement Rate]]+Table2[[#This Row],[Click through rate]])*100 -> 6.0185634
A30: A29 | B30: LinkedIn | C30: 45910 | D30: Carousel | E30: #MacBookProM3 | G30: 9266 | H30: 999 | I30: 928 | J30: 2700 | K30: 12264 | L30: 128397 | M30: Apple Event September 2025 | N30: =(G30+H30+I30)/L30 -> 0.087174934 | O30: =Table2[[#This Row],[Shares]]/Table2[[#This Row],[Impressions]] -> 0.0077805556 | P30: =(Table2[[#This Row],[Engagement Rate]]+Table2[[#This Row],[Click through rate]])*100 -> 9.495549
A31: A30 | B31: LinkedIn | C31: 45713 | D31: Carousel | E31: #iPhonePhotography | F31: #ShotOniPhone | G31: 10702 | H31: 621 | I31: 445 | J31: 2918 | K31: 54808 | L31: 220225 | M31: Apple Watch Ultra 2 Launch | N31: =(G31+H31+I31)/L31 -> 0.053436258 | O31: =Table2[[#This Row],[Shares]]/Table2[[#This Row],[Impressions]] -> 0.0028198433 | P31: =(Table2[[#This Row],[Engagement Rate]]+Table2[[#This Row],[Click through rate]])*100 -> 5.6256102
A32: A31 | B32: Instagram | C32: 45642 | D32: Image | E32: #AppleEvent | F32: #iPadPro | G32: 2384 | H32: 1246 | I32: 160 | J32: 2004 | K32: 2701 | L32: 73142 | M32: Apple Watch Ultra 2 Launch | N32: =(G32+H32+I32)/L32 -> 0.051817013 | O32: =Table2[[#This Row],[Shares]]/Table2[[#This Row],[Impressions]] -> 0.017035356 | P32: =(Table2[[#This Row],[Engagement Rate]]+Table2[[#This Row],[Click through rate]])*100 -> 6.8852369
A33: A32 | B33: Instagram | C33: 45504 | D33: Image | E33: #AppleEvent | F33: #iPhone16 | G33: 2404 | H33: 774 | I33: 661 | J33: 662 | K33: 12676 | L33: 66916 | M33: Apple Watch Ultra 2 Launch | N33: =(G33+H33+I33)/L33 -> 0.057370435 | O33: =Table2[[#This Row],[Shares]]/Table2[[#This Row],[Impressions]] -> 0.01156674 | P33: =(Table2[[#This Row],[Engagement Rate]]+Table2[[#This Row],[Click through rate]])*100 -> 6.8937175
A34: A33 | B34: LinkedIn | C34: 45911 | D34: Carousel | E34: #iPhone16Launch | F34: #AppleEvent | G34: 10175 | H34: 342 | I34: 825 | J34: 2904 | K34: 15954 | L34: 104324 | M34: Apple Event September 2025 | N34: =(G34+H34+I34)/L34 -> 0.10871899 | O34: =Table2[[#This Row],[Shares]]/Table2[[#This Row],[Impressions]] -> 0.0032782485 | P34: =(Table2[[#This Row],[Engagement Rate]]+Table2[[#This Row],[Click through rate]])*100 -> 11.199724
A35: A34 | B35: Twitter | C35: 45912 | D35: Tweet | E35: #AppleDesign | F35: #Innovation | G35: 17158 | H35: 1192 | I35: 262 | J35: 2016 | K35: 28771 | L35: 216037 | M35: Apple Event September 2025 | N35: =(G35+H35+I35)/L35 -> 0.086151909 | O35: =Table2[[#This Row],[Shares]]/Table2[[#This Row],[Impressions]] -> 0.0055175734 | P35: =(Table2[[#This Row],[Engagement Rate]]+Table2[[#This Row],[Click through rate]])*100 -> 9.1669483
A36: A35 | B36: Twitter | C36: 45626 | D36: Video | E36: #AppleEvent | F36: #iPhone16 | G36: 14763 | H36: 864 | I36: 336 | J36: 1493 | K36: 33310 | L36: 165932 | M36: iPhone 16 Launch | N36: =(G36+H36+I36)/L36 -> 0.096202059 | O36: =Table2[[#This Row],[Shares]]/Table2[[#This Row],[Impressions]] -> 0.0052069522 | P36: =(Table2[[#This Row],[Engagement Rate]]+Table2[[#This Row],[Click through rate]])*100 -> 10.140901
A37: A36 | B37: Instagram | C37: 45766 | D37: Carousel | E37: #MacBookProM3 | G37: 20384 | H37: 344 | I37: 956 | J37: 655 | K37: 67621 | L37: 175720 | M37: Sustainability Awareness Drive | N37: =(G37+H37+I37)/L37 -> 0.12340087 | O37: =Table2[[#This Row],[Shares]]/Table2[[#This Row],[Impressions]] -> 0.0019576599 | P37: =(Table2[[#This Row],[Engagement Rate]]+Table2[[#This Row],[Click through rate]])*100 -> 12.535852
A38: A37 | B38: LinkedIn | C38: 45663 | D38: Image | E38: #AppleDesign | F38: #Innovation | G38: 11860 | H38: 1448 | I38: 893 | J38: 490 | K38: 23518 | L38: 206205 | M38: Apple Watch Ultra 2 Launch | N38: =(G38+H38+I38)/L38 -> 0.068868359 | O38: =Table2[[#This Row],[Shares]]/Table2[[#This Row],[Impressions]] -> 0.0070221382 | P38: =(Table2[[#This Row],[Engagement Rate]]+Table2[[#This Row],[Click through rate]])*100 -> 7.5890497
A39: A38 | B39: Instagram | C39: 45705 | D39: Tweet | E39: #MacBookAirM3 | F39: #AppleInnovation | G39: 7989 | H39: 1206 | I39: 376 | J39: 2769 | K39: 27550 | L39: 221749 | M39: Sustainability Awareness Drive | N39: =(G39+H39+I39)/L39 -> 0.043161412 | O39: =Table2[[#This Row],[Shares]]/Table2[[#This Row],[Impressions]] -> 0.0054385815 | P39: =(Table2[[#This Row],[Engagement Rate]]+Table2[[#This Row],[Click through rate]])*100 -> 4.8599994
A40: A39 | B40: Instagram | C40: 45913 | D40: Carousel | E40: #AppleMusic | F40: #AppleLifestyle | G40: 17106 | H40: 702 | I40: 459 | J40: 999 | K40: 59627 | L40: 136059 | M40: Apple Event September 2025 | N40: =(G40+H40+I40)/L40 -> 0.13425793 | O40: =Table2[[#This Row],[Shares]]/Table2[[#This Row],[Impressions]] -> 0.0051595264 | P40: =(Table2[[#This Row],[Engagement Rate]]+Table2[[#This Row],[Click through rate]])*100 -> 13.941746
A41: A40 | B41: YouTube | C41: 45914 | D41: Carousel | E41: #AppleWatch | F41: #Health | G41: 19844 | H41: 1020 | I41: 247 | J41: 2354 | K41: 37792 | L41: 138317 | M41: Apple Event September 2025 | N41: =(G41+H41+I41)/L41 -> 0.15262766 | O41: =Table2[[#This Row],[Shares]]/Table2[[#This Row],[Impressions]] -> 0.0073743647 | P41: =(Table2[[#This Row],[Engagement Rate]]+Table2[[#This Row],[Click through rate]])*100 -> 16.000202
A42: A41 | B42: YouTube | C42: 45915 | D42: Tweet | E42: #MacBookAirM3 | F42: #AppleInnovation | G42: 5636 | H42: 303 | I42: 204 | J42: 2480 | K42: 7377 | L42: 241207 | M42: Apple Event September 2025 | N42: =(G42+H42+I42)/L42 -> 0.025467752 | O42: =Table2[[#This Row],[Shares]]/Table2[[#This Row],[Impressions]] -> 0.0012561824 | P42: =(Table2[[#This Row],[Engagement Rate]]+Table2[[#This Row],[Click through rate]])*100 -> 2.6723934
A43: A42 | B43: YouTube | C43: 45721 | D43: Carousel | E43: #AppleEvent | F43: #iPhone16 | G43: 12916 | H43: 1262 | I43: 772 | J43: 856 | K43: 11496 | L43: 75046 | M43: Sustainability Awareness Drive | N43: =(G43+H43+I43)/L43 -> 0.19921115 | O43: =Table2[[#This Row],[Shares]]/Table2[[#This Row],[Impressions]] -> 0.016816353 | P43: =(Table2[[#This Row],[Engagement Rate]]+Table2[[#This Row],[Click through rate]])*100 -> 21.60275
A44: A43 | B44: Twitter | C44: 45916 | D44: Tweet | E44: #MacBookProM3 | G44: 6809 | H44: 397 | I44: 813 | J44: 1125 | K44: 12206 | L44: 218136 | M44: Apple Event September 2025 | N44: =(G44+H44+I44)/L44 -> 0.03676147 | O44: =Table2[[#This Row],[Shares]]/Table2[[#This Row],[Impressions]] -> 0.0018199655 | P44: =(Table2[[#This Row],[Engagement Rate]]+Table2[[#This Row],[Click through rate]])*100 -> 3.8581435
A45: A44 | B45: LinkedIn | C45: 45718 | D45: Video | E45: #iPhonePhotography | F45: #ShotOniPhone | G45: 22562 | H45: 778 | I45: 907 | J45: 1354 | K45: 34475 | L45: 141459 | M45: iPhone 16 Launch | N45: =(G45+H45+I45)/L45 -> 0.17140656 | O45: =Table2[[#This Row],[Shares]]/Table2[[#This Row],[Impressions]] -> 0.0054998268 | P45: =(Table2[[#This Row],[Engagement Rate]]+Table2[[#This Row],[Click through rate]])*100 -> 17.690638
A46: A45 | B46: LinkedIn | C46: 45917 | D46: Tweet | E46: #AppleMusic | F46: #AppleLifestyle | G46: 15456 | H46: 590 | I46: 555 | J46: 2882 | K46: 49816 | L46: 240422 | M46: Apple Event September 2025 | N46: =(G46+H46+I46)/L46 -> 0.069049421 | O46: =Table2[[#This Row],[Shares]]/Table2[[#This Row],[Impressions]] -> 0.0024540184 | P46: =(Table2[[#This Row],[Engagement Rate]]+Table2[[#This Row],[Click through rate]])*100 -> 7.150344
A47: A46 | B47: LinkedIn | C47: 45779 | D47: Tweet | E47: #AppleEvent | F47: #iPhone16 | G47: 17444 | H47: 1402 | I47: 218 | J47: 725 | K47: 8710 | L47: 85893 | M47: MacBook Air M3 Campaign | N47: =(G47+H47+I47)/L47 -> 0.22195057 | O47: =Table2[[#This Row],[Shares]]/Table2[[#This Row],[Impressions]] -> 0.016322634 | P47: =(Table2[[#This Row],[Engagement Rate]]+Table2[[#This Row],[Click through rate]])*100 -> 23.82732
A48: A47 | B48: LinkedIn | C48: 45712 | D48: Tweet | E48: #iPhone16Launch | F48: #AppleEvent | G48: 24984 | H48: 753 | I48: 461 | J48: 2710 | K48: 20792 | L48: 141520 | M48: Sustainability Awareness Drive | N48: =(G48+H48+I48)/L48 -> 0.18511871 | O48: =Table2[[#This Row],[Shares]]/Table2[[#This Row],[Impressions]] -> 0.0053208027 | P48: =(Table2[[#This Row],[Engagement Rate]]+Table2[[#This Row],[Click through rate]])*100 -> 19.043951
...

Sheet Hashtags
A1: PostID | B1: Platform | C1: Date | D1: ContentType | E1: Likes | F1: Shares | G1: Comments | H1: Clicks | I1: Reach | J1: Impressions | K1: Campaign | L1: Engagement Rate | M1: Hashtags | N1: Click through rate | O1: Performance
A2: A1 | B2: YouTube | C2: 45649 | D2: Image | E2: 24516 | F2: 976 | G2: 974 | H2: 2675 | I2: 23275 | J2: 202932 | K2: Apple Watch Ultra 2 Launch | L2: 0.13041807 | M2: #AppleWatchUltra2 | N2: =Hashtags!$H2/Hashtags!$J2 -> 0.013181755 | O2: =(Hashtags!$L2+Hashtags!$N2)*100 -> 14.359983
A3: A1 | B3: YouTube | C3: 45649 | D3: Image | E3: 24516 | F3: 976 | G3: 974 | H3: 2675 | I3: 23275 | J3: 202932 | K3: Apple Watch Ultra 2 Launch | L3: 0.13041807 | M3: #HealthTech | N3: =Hashtags!$H3/Hashtags!$J3 -> 0.013181755 | O3: =(Hashtags!$L3+Hashtags!$N3)*100 -> 14.359983
A4: A2 | B4: LinkedIn | C4: 45903 | D4: Image | E4: 4779 | F4: 1110 | G4: 436 | H4: 1574 | I4: 77167 | J4: 71585 | K4: Apple Event September 2025 | L4: 0.088356499 | M4: #MacBookAirM3 | N4: =Hashtags!$H4/Hashtags!$J4 -> 0.021987847 | O4: =(Hashtags!$L4+Hashtags!$N4)*100 -> 11.034435
A5: A2 | B5: LinkedIn | C5: 45903 | D5: Image | E5: 4779 | F5: 1110 | G5: 436 | H5: 1574 | I5: 77167 | J5: 71585 | K5: Apple Event September 2025 | L5: 0.088356499 | M5: #AppleInnovation | N5: =Hashtags!$H5/Hashtags!$J5 -> 0.021987847 | O5: =(Hashtags!$L5+Hashtags!$N5)*100 -> 11.034435
A6: A3 | B6: Instagram | C6: 45789 | D6: Tweet | E6: 19308 | F6: 1318 | G6: 795 | H6: 1499 | I6: 52307 | J6: 193087 | K6: Sustainability Awareness Drive | L6: 0.11093963 | M6: #AppleDesign | N6: =Hashtags!$H6/Hashtags!$J6 -> 0.0077633398 | O6: =(Hashtags!$L6+Hashtags!$N6)*100 -> 11.870297
A7: A3 | B7: Instagram | C7: 45789 | D7: Tweet | E7: 19308 | F7: 1318 | G7: 795 | H7: 1499 | I7: 52307 | J7: 193087 | K7: Sustainability Awareness Drive | L7: 0.11093963 | M7: #Innovation | N7: =Hashtags!$H7/Hashtags!$J7 -> 0.0077633398 | O7: =(Hashtags!$L7+Hashtags!$N7)*100 -> 11.870297
A8: A4 | B8: YouTube | C8: 45516 | D8: Video | E8: 3581 | F8: 517 | G8: 880 | H8: 1925 | I8: 18636 | J8: 248611 | K8: iPhone 16 Launch | L8: 0.020023249 | M8: #AppleEvent | N8: =Hashtags!$H8/Hashtags!$J8 -> 0.0077430202 | O8: =(Hashtags!$L8+Hashtags!$N8)*100 -> 2.7766269
A9: A4 | B9: YouTube | C9: 45516 | D9: Video | E9: 3581 | F9: 517 | G9: 880 | H9: 1925 | I9: 18636 | J9: 248611 | K9: iPhone 16 Launch | L9: 0.020023249 | M9: #iPadPro | N9: =Hashtags!$H9/Hashtags!$J9 -> 0.0077430202 | O9: =(Hashtags!$L9+Hashtags!$N9)*100 -> 2.7766269
A10: A5 | B10: YouTube | C10: 45904 | D10: Video | E10: 21708 | F10: 435 | G10: 317 | H10: 1213 | I10: 70701 | J10: 83585 | K10: Apple Event September 2025 | L10: 0.2687085 | M10: #AppleWatchUltra2 | N10: =Hashtags!$H10/Hashtags!$J10 -> 0.014512173 | O10: =(Hashtags!$L10+Hashtags!$N10)*100 -> 28.322067
A11: A5 | B11: YouTube | C11: 45904 | D11: Video | E11: 21708 | F11: 435 | G11: 317 | H11: 1213 | I11: 70701 | J11: 83585 | K11: Apple Event September 2025 | L11: 0.2687085 | M11: #HealthTech | N11: =Hashtags!$H11/Hashtags!$J11 -> 0.014512173 | O11: =(Hashtags!$L11+Hashtags!$N11)*100 -> 28.322067
A12: A6 | B12: LinkedIn | C12: 45905 | D12: Image | E12: 14677 | F12: 533 | G12: 759 | H12: 753 | I12: 23275 | J12: 66958 | K12: Apple Event September 2025 | L12: 0.23849279 | M12: #ShotOniPhone | N12: =Hashtags!$H12/Hashtags!$J12 -> 0.011245856 | O12: =(Hashtags!$L12+Hashtags!$N12)*100 -> 24.973864
A13: A7 | B13: Instagram | C13: 45467 | D13: Carousel | E13: 7713 | F13: 575 | G13: 417 | H13: 336 | I13: 61660 | J13: 66017 | K13: iPhone 16 Launch | L13: 0.13185998 | M13: #AppleMusic | N13: =Hashtags!$H13/Hashtags!$J13 -> 0.0050895981 | O13: =(Hashtags!$L13+Hashtags!$N13)*100 -> 13.694957
... A568: A300 | B568: LinkedIn | C568: 45926 | D568: Video | E568: 21216 | F568: 226 | G568: 187 | H568: 1573 | I568: 62688 | J568: 111031 | K568: Apple Event September 2025 | L568: 0.19480145 | M568: #AppleEvent | N568: =Hashtags!$H568/Hashtags!$J568 -> 0.014167215 | O568: =(Hashtags!$L568+Hashtags!$N568)*100 -> 20.896867

Sheet Campaign Metadata
A1: Campaign_Name | B1: Start_Date | C1: End_Date | D1: Objective | E1: Ad_Spend | F1: Impressions | G1: Engagement_Uplift | H1: Follower Gain
A2: iPhone 16 Launch | B2: 45458 | C2: 45488 | D2: Product Launch | E2: 85000 | F2: 950000 | G2: 0.45 | H2: =SUMIFS( Table8_1[Follower Gain],Table8_1[Week_Start_Date],">="&Table1[[#This Row],[Start_Date]],Table8_1[Week_Start_Date],"<="&Table1[[#This Row],[End_Date]]) -> 106800
A3: MacBook Air M3 Campaign | B3: 45566 | C3: 45596 | D3: Product Promotion | E3: 60000 | F3: 780000 | G3: 0.38 | H3: =SUMIFS( Table8_1[Follower Gain],Table8_1[Week_Start_Date],">="&Table1[[#This Row],[Start_Date]],Table8_1[Week_Start_Date],"<="&Table1[[#This Row],[End_Date]]) -> 99093
A4: Apple Watch Ultra 2 Launch | B4: 45651 | C4: 45667 | D4: Health & Fitness Awareness | E4: 55000 | F4: 700000 | G4: 0.41 | H4: =SUMIFS( Table8_1[Follower Gain],Table8_1[Week_Start_Date],">="&Table1[[#This Row],[Start_Date]],Table8_1[Week_Start_Date],"<="&Table1[[#This Row],[End_Date]]) -> 50927
A5: Sustainability Awareness Drive | B5: 45717 | C5: 45747 | D5: Sustainability Branding | E5: 40000 | F5: 550000 | G5: 0.32 | H5: =SUMIFS( Table8_1[Follower Gain],Table8_1[Week_Start_Date],">="&Table1[[#This Row],[Start_Date]],Table8_1[Week_Start_Date],"<="&Table1[[#This Row],[End_Date]]) -> 107259
A6: Apple Event September 2025 | B6: 45901 | C6: 45930 | D6: Brand Engagement | E6: 75000 | F6: 880000 | G6: 0.47 | H6: =SUMIFS( Table8_1[Follower Gain],Table8_1[Week_Start_Date],">="&Table1[[#This Row],[Start_Date]],Table8_1[Week_Start_Date],"<="&Table1[[#This Row],[End_Date]]) -> 0

Sheet Engagement Summary
A1: Week_Start_Date | B1: Platform | C1: New_Followers | D1: Unfollows | E1: Total_Followers | F1: Engagement_Rate | G1: Ad_Spend | H1: Growth Rate | I1: Follower Gain
A2: 45446 | B2: Instagram | C2: 4138 | D2: 361 | E2: 103777 | F2: 56.637791 | G2: 23944 | H2: 0.036395348 | I2: 3777
A3: 45446 | B3: Twitter | C3: 8693 | D3: 1261 | E3: 111209 | F3: 69.475492 | G3: 29873 | H3: 0.066829124 | I3: 7432
A4: 45446 | B4: YouTube | C4: 9264 | D4: 1141 | E4: 119332 | F4: 92.312205 | G4: 50372 | H4: 0.068070593 | I4: 8123
A5: 45446 | B5: YouTube | C5: 8842 | D5: 971 | E5: 127203 | F5: 16.351816 | G5: 33928 | H5: 0.061877471 | I5: 7871
A6: 45453 | B6: Instagram | C6: 7721 | D6: 506 | E6: 134418 | F6: 35.577824 | G6: 25379 | H6: 0.053675847 | I6: 7215
A7: 45453 | B7: YouTube | C7: 8002 | D7: 524 | E7: 141896 | F7: 52.064893 | G7: 46751 | H7: 0.052700569 | I7: 7478
A8: 45453 | B8: Twitter | C8: 5225 | D8: 291 | E8: 146830 | F8: 19.551863 | G8: 44546 | H8: 0.033603487 | I8: 4934
A9: 45453 | B9: Twitter | C9: 3978 | D9: 543 | E9: 150265 | F9: 49.159818 | G9: 34286 | H9: 0.022859615 | I9: 3435
A10: 45460 | B10: Instagram | C10: 8373 | D10: 921 | E10: 157717 | F10: 12.226329 | G10: 15110 | H10: 0.047249187 | I10: 7452
A11: 45460 | B11: Twitter | C11: 6907 | D11: 834 | E11: 163790 | F11: 54.158984 | G11: 22087 | H11: 0.037077966 | I11: 6073
A12: 45460 | B12: LinkedIn | C12: 7097 | D12: 369 | E12: 170518 | F12: 9.2506363 | G12: 33762 | H12: 0.039456245 | I12: 6728
A13: 45460 | B13: Instagram | C13: 6656 | D13: 978 | E13: 176196 | F13: 60.425889 | G13: 27081 | H13: 0.032225476 | I13: 5678
... A201: 45789 | B201: Twitter | C201: 8527 | D201: 1091 | E201: 1186398 | F201: 1.6760817 | G201: 41703 | H201: 0.0062677112 | I201: 7436

Sheet Engagement Analysis
A1: Top 10 Apple posts with highest engagement rate
A2: PostID | B2: Platform | C2: Date | D2: ContentType | E2: Hashtags.1 | F2: Hashtags.2 | G2: Likes | H2: Shares | I2: Comments | J2: Clicks | K2: Reach | L2: Impressions | M2: Campaign | N2: Engagement Rate
A3: A1 | B3: YouTube | C3: 45649 | D3: Image | E3: #AppleWatchUltra2 | F3: #HealthTech | G3: 24516 | H3: 976 | I3: 974 | J3: 2675 | K3: 23275 | L3: 202932 | M3: Apple Watch Ultra 2 Launch | N3: =(G3+H3+I3)/L3 -> 0.13041807
A4: A2 | B4: LinkedIn | C4: 45903 | D4: Image | E4: #MacBookAirM3 | F4: #AppleInnovation | G4: 4779 | H4: 1110 | I4: 436 | J4: 1574 | K4: 77167 | L4: 71585 | M4: Apple Event September 2025 | N4: =(G4+H4+I4)/L4 -> 0.088356499
A5: A3 | B5: Instagram | C5: 45789 | D5: Tweet | E5: #AppleDesign | F5: #Innovation | G5: 19308 | H5: 1318 | I5: 795 | J5: 1499 | K5: 52307 | L5: 193087 | M5: Sustainability Awareness Drive | N5: =(G5+H5+I5)/L5 -> 0.11093963
A6: A4 | B6: YouTube | C6: 45516 | D6: Video | E6: #AppleEvent | F6: #iPadPro | G6: 3581 | H6: 517 | I6: 880 | J6: 1925 | K6: 18636 | L6: 248611 | M6: iPhone 16 Launch | N6: =(G6+H6+I6)/L6 -> 0.020023249
A7: A5 | B7: YouTube | C7: 45904 | D7: Video | E7: #AppleWatchUltra2 | F7: #HealthTech | G7: 21708 | H7: 435 | I7: 317 | J7: 1213 | K7: 70701 | L7: 83585 | M7: Apple Event September 2025 | N7: =(G7+H7+I7)/L7 -> 0.2687085
A8: A6 | B8: LinkedIn | C8: 45905 | D8: Image | E8: #ShotOniPhone | G8: 14677 | H8: 533 | I8: 759 | J8: 753 | K8: 23275 | L8: 66958 | M8: Apple Event September 2025 | N8: =(G8+H8+I8)/L8 -> 0.23849279
A9: A7 | B9: Instagram | C9: 45467 | D9: Carousel | E9: #AppleMusic | F9: #AppleLifestyle | G9: 7713 | H9: 575 | I9: 417 | J9: 336 | K9: 61660 | L9: 66017 | M9: iPhone 16 Launch | N9: =(G9+H9+I9)/L9 -> 0.13185998
A10: A8 | B10: Instagram | C10: 45486 | D10: Video | E10: #AppleWatch | F10: #Health | G10: 18639 | H10: 1360 | I10: 898 | J10: 2011 | K10: 42841 | L10: 247779 | M10: iPhone 16 Launch | N10: =(G10+H10+I10)/L10 -> 0.084337252
A11: A9 | B11: YouTube | C11: 45534 | D11: Carousel | E11: #MacBookAirM3 | F11: #AppleInnovation | G11: 6804 | H11: 787 | I11: 970 | J11: 1095 | K11: 56343 | L11: 164677 | M11: Apple Watch Ultra 2 Launch | N11: =(G11+H11+I11)/L11 -> 0.051986616
A12: A10 | B12: Twitter | C12: 45727 | D12: Video | E12: #iPhone16Launch | F12: #AppleEvent | G12: 20222 | H12: 712 | I12: 604 | J12: 1272 | K12: 71598 | L12: 216422 | M12: Sustainability Awareness Drive | N12: =(G12+H12+I12)/L12 -> 0.099518533
A13: A11 | B13: YouTube | C13: 45690 | D13: Carousel | E13: #AppleEvent | F13: #iPadPro | G13: 12136 | H13: 1117 | I13: 834 | J13: 892 | K13: 24675 | L13: 183273 | M13: Sustainability Awareness Drive | N13: =(G13+H13+I13)/L13 -> 0.076863477
A14: A12 | B14: YouTube | C14: 45494 | D14: Tweet | E14: #MacBookAirM3 | F14: #AppleInnovation | G14: 2009 | H14: 1072 | I14: 550 | J14: 1437 | K14: 22982 | L14: 69426 | M14: iPhone 16 Launch | N14: =(G14+H14+I14)/L14 -> 0.052300291
A15: A82 | B15: LinkedIn | C15: 45497 | D15: Video | E15: #AppleMusic | F15: #AppleLifestyle | G15: 22914 | H15: 954 | I15: 584 | J15: 1519 | K15: 13637 | L15: 49847 | M15: Apple Watch Ultra 2 Launch | N15: =(G15+H15+I15)/L15 -> 0.49054106
A16: A14 | B16: YouTube | C16: 45906 | D16: Tweet | E16: #AppleWatch | F16: #Health | G16: 7124 | H16: 469 | I16: 851 | J16: 2571 | K16: 33802 | L16: 216313 | M16: Apple Event September 2025 | N16: =(G16+H16+I16)/L16 -> 0.039036026
A17: A15 | B17: LinkedIn | C17: 45907 | D17: Tweet | E17: #AppleDesign | F17: #Innovation | G17: 3015 | H17: 997 | I17: 783 | J17: 617 | K17: 77167 | L17: 82229 | M17: Apple Event September 2025 | N17: =(G17+H17+I17)/L17 -> 0.058312761
A18: A16 | B18: Instagram | C18: 45530 | D18: Carousel | E18: #AppleWatch | F18: #Health | G18: 4193 | H18: 924 | I18: 707 | J18: 2696 | K18: 55075 | L18: 126652 | M18: iPhone 16 Launch | N18: =(G18+H18+I18)/L18 -> 0.045984272
A19: A17 | B19: LinkedIn | C19: 45782 | D19: Tweet | E19: #AppleEvent | F19: #iPhone16 | G19: 10415 | H19: 1388 | I19: 725 | J19: 2462 | K19: 53082 | L19: 168267 | M19: MacBook Air M3 Campaign | N19: =(G19+H19+I19)/L19 -> 0.074453101
A20: A18 | B20: LinkedIn | C20: 45523 | D20: Image | E20: #AppleWatch | F20: #Health | G20: 15550 | H20: 204 | I20: 279 | J20: 1646 | K20: 35819 | L20: 219436 | M20: Apple Watch Ultra 2 Launch | N20: =(G20+H20+I20)/L20 -> 0.073064584
... A29: A27 | B29: Twitter | C29: 45552 | D29: Tweet | E29: #iPhone16Launch | F29: #AppleEvent | G29: 20017 | H29: 495 | I29: 178 | J29: 2683 | K29: 32244 | L29: 182633 | M29: Apple Watch Ultra 2 Launch | N29: =(G29+H29+I29)/L29 -> 0.1132873
A30: A28 | B30: Twitter | C30: 45720 | D30: Tweet | E30: #ShotOniPhone | G30: 12344 | H30: 815 | I30: 298 | J30: 2439 | K30: 6259 | L30: 237133 | M30: iPhone 16 Launch | N30: =(G30+H30+I30)/L30 -> 0.056748744
A31: A29 | B31: LinkedIn | C31: 45910 | D31: Carousel | E31: #MacBookProM3 | G31: 9266 | H31: 999 | I31: 928 | J31: 2700 | K31: 12264 | L31: 128397 | M31: Apple Event September 2025 | N31: =(G31+H31+I31)/L31 -> 0.087174934
A32: A30 | B32: LinkedIn | C32: 45713 | D32: Carousel | E32: #iPhonePhotography | F32: #ShotOniPhone | G32: 10702 | H32: 621 | I32: 445 | J32: 2918 | K32: 54808 | L32: 220225 | M32: Apple Watch Ultra 2 Launch | N32: =(G32+H32+I32)/L32 -> 0.053436258
A33: A31 | B33: Instagram | C33: 45642 | D33: Image | E33: #AppleEvent | F33: #iPadPro | G33: 2384 | H33: 1246 | I33: 160 | J33: 2004 | K33: 2701 | L33: 73142 | M33: Apple Watch Ultra 2 Launch | N33: =(G33+H33+I33)/L33 -> 0.051817013
A34: A32 | B34: Instagram | C34: 45504 | D34: Image | E34: #AppleEvent | F34: #iPhone16 | G34: 2404 | H34: 774 | I34: 661 | J34: 662 | K34: 12676 | L34: 66916 | M34: Apple Watch Ultra 2 Launch | N34: =(G34+H34+I34)/L34 -> 0.057370435
A35: A33 | B35: LinkedIn | C35: 45911 | D35: Carousel | E35: #iPhone16Launch | F35: #AppleEvent | G35: 10175 | H35: 342 | I35: 825 | J35: 2904 | K35: 15954 | L35: 104324 | M35: Apple Event September 2025 | N35: =(G35+H35+I35)/L35 -> 0.10871899
A36: A34 | B36: Twitter | C36: 45912 | D36: Tweet | E36: #AppleDesign | F36: #Innovation | G36: 17158 | H36: 1192 | I36: 262 | J36: 2016 | K36: 28771 | L36: 216037 | M36: Apple Event September 2025 | N36: =(G36+H36+I36)/L36 -> 0.086151909
A37: A35 | B37: Twitter | C37: 45626 | D37: Video | E37: #AppleEvent | F37: #iPhone16 | G37: 14763 | H37: 864 | I37: 336 | J37: 1493 | K37: 33310 | L37: 165932 | M37: iPhone 16 Launch | N37: =(G37+H37+I37)/L37 -> 0.096202059
A38: A36 | B38: Instagram | C38: 45766 | D38: Carousel | E38: #MacBookProM3 | G38: 20384 | H38: 344 | I38: 956 | J38: 655 | K38: 67621 | L38: 175720 | M38: Sustainability Awareness Drive | N38: =(G38+H38+I38)/L38 -> 0.12340087
A39: A37 | B39: LinkedIn | C39: 45663 | D39: Image | E39: #AppleDesign | F39: #Innovation | G39: 11860 | H39: 1448 | I39: 893 | J39: 490 | K39: 23518 | L39: 206205 | M39: Apple Watch Ultra 2 Launch | N39: =(G39+H39+I39)/L39 -> 0.068868359
A40: A38 | B40: Instagram | C40: 45705 | D40: Tweet | E40: #MacBookAirM3 | F40: #AppleInnovation | G40: 7989 | H40: 1206 | I40: 376 | J40: 2769 | K40: 27550 | L40: 221749 | M40: Sustainability Awareness Drive | N40: =(G40+H40+I40)/L40 -> 0.043161412
A41: A39 | B41: Instagram | C41: 45913 | D41: Carousel | E41: #AppleMusic | F41: #AppleLifestyle | G41: 17106 | H41: 702 | I41: 459 | J41: 999 | K41: 59627 | L41: 136059 | M41: Apple Event September 2025 | N41: =(G41+H41+I41)/L41 -> 0.13425793
A42: A40 | B42: YouTube | C42: 45914 | D42: Carousel | E42: #AppleWatch | F42: #Health | G42: 19844 | H42: 1020 | I42: 247 | J42: 2354 | K42: 37792 | L42: 138317 | M42: Apple Event September 2025 | N42: =(G42+H42+I42)/L42 -> 0.15262766
A43: A41 | B43: YouTube | C43: 45915 | D43: Tweet | E43: #MacBookAirM3 | F43: #AppleInnovation | G43: 5636 | H43: 303 | I43: 204 | J43: 2480 | K43: 7377 | L43: 241207 | M43: Apple Event September 2025 | N43: =(G43+H43+I43)/L43 -> 0.025467752
A44: A42 | B44: YouTube | C44: 45721 | D44: Carousel | E44: #AppleEvent | F44: #iPhone16 | G44: 12916 | H44: 1262 | I44: 772 | J44: 856 | K44: 11496 | L44: 75046 | M44: Sustainability Awareness Drive | N44: =(G44+H44+I44)/L44 -> 0.19921115
A45: A43 | B45: Twitter | C45: 45916 | D45: Tweet | E45: #MacBookProM3 | G45: 6809 | H45: 397 | I45: 813 | J45: 1125 | K45: 12206 | L45: 218136 | M45: Apple Event September 2025 | N45: =(G45+H45+I45)/L45 -> 0.03676147
A46: A44 | B46: LinkedIn | C46: 45718 | D46: Video | E46: #iPhonePhotography | F46: #ShotOniPhone | G46: 22562 | H46: 778 | I46: 907 | J46: 1354 | K46: 34475 | L46: 141459 | M46: iPhone 16 Launch | N46: =(G46+H46+I46)/L46 -> 0.17140656
A47: A45 | B47: LinkedIn | C47: 45917 | D47: Tweet | E47: #AppleMusic | F47: #AppleLifestyle | G47: 15456 | H47: 590 | I47: 555 | J47: 2882 | K47: 49816 | L47: 240422 | M47: Apple Event September 2025 | N47: =(G47+H47+I47)/L47 -> 0.069049421
A48: A46 | B48: LinkedIn | C48: 45779 | D48: Tweet | E48: #AppleEvent | F48: #iPhone16 | G48: 17444 | H48: 1402 | I48: 218 | J48: 725 | K48: 8710 | L48: 85893 | M48: MacBook Air M3 Campaign | N48: =(G48+H48+I48)/L48 -> 0.22195057
...

Sheet Platform Analysis
A1: Platform with highest engagement
A2: Row Labels | B2: Sum of Engagement
A3: LinkedIn | B3: 1255026
A4: Twitter | B4: 1136557
A5: YouTube | B5: 1058347
A6: Instagram | B6: 1051187
A8: Follower growth rates across platforms
A9: Row Labels | B9: Sum of Growth rate
A10: Instagram | B10: 0.29298233
A11: Twitter | B11: 0.16021218
A12: LinkedIn | B12: 0.14051571
A13: YouTube | B13: 0.044748618
A14: Grand Total | B14: 0.63845883 | D14: LinkedIn Has Highest Engagement among all Platforms | I14: Instagram has achieved 46% Follower Growth ,the Highest Among all platforms
A18: Visualize Engagement vs. Ad Spend per platform.
A20: Row Labels | B20: Sum of Engagement | D20: Custom table to compare
A21: YouTube | B21: 1058347 | D21: Platform | E21: Engagement | F21: Ad Spend
A22: Twitter | B22: 1136557 | D22: YouTube | E22: 1058347 | F22: 128749
A23: LinkedIn | B23: 1255026 | D23: Twitter | E23: 1136557 | F23: 349633
A24: Instagram | B24: 1051187 | D24: LinkedIn | E24: 1255026 | F24: 607249
D25: Instagram | E25: 1051187 | F25: 596089
A27: Row Labels | B27: Sum of Ad_Spend
A28: YouTube | B28: 128749
A29: Twitter | B29: 349633
A30: LinkedIn | B30: 607249
A31: Instagram | B31: 596089
A33: Key findings and recommendation

Sheet Content Strategy
A2: =PROPER("the most frequently used Apple hashtags") -> The Most Frequently Used Apple Hashtags | D2: Average performance of posts | G2: Content performance
A3: Row Labels | B3: Count of Hashtags | D3: Row Labels | E3: Average of Performance | G3: Row Labels | H3: Sum of performance
A4: #AppleEvent | B4: 80 | D4: #AppleWatchUltra2 | E4: 15.935958 | G4: Carousel
A5: #ShotOniPhone | B5: 41 | D5: #HealthTech | E5: 15.935958 | G5: Health & Fitness Awareness | H5: 305.00199
A6: #AppleWatch | B6: 37 | D6: #ShotOniPhone | E6: 14.819258 | G6: Product Launch | H6: 296.57134
A7: #Health | B7: 37 | D7: #AppleLifestyle | E7: 14.78072 | G7: Brand Engagement | H7: 262.31891
A8: #AppleMusic | B8: 34 | D8: #AppleMusic | E8: 14.78072 | G8: Product Promotion | H8: 242.42386
A9: #AppleLifestyle | B9: 34 | D9: #iPhone16 | E9: 13.774529 | G9: Sustainability Branding | H9: 143.33744
A10: #iPhone16 | B10: 32 | D10: #Sustainability | E10: 13.561432 | G10: Video
A11: #iPhone16Launch | B11: 29 | D11: #AppleEarth | E11: 13.561432 | G11: Health & Fitness Awareness | H11: 330.07118
A12: #MacBookAirM3 | B12: 28 | D12: #iPhonePhotography | E12: 13.377277 | G12: Sustainability Branding | H12: 303.99015
A13: #AppleInnovation | B13: 28 | D13: #MacBookAirM3 | E13: 13.328924 | G13: Brand Engagement | H13: 203.12694
A14: #Innovation | B14: 25 | D14: #AppleInnovation | E14: 13.328924 | G14: Product Launch | H14: 157.20892
A15: #iPhonePhotography | B15: 25 | D15: #AppleEvent | E15: 13.054496 | G15: Product Promotion | H15: 92.691714
A16: #AppleDesign | B16: 25 | D16: #iPhone16Launch | E16: 12.725525 | G16: Tweet
A17: #AppleWatchUltra2 | B17: 25 | D17: #AppleWatch | E17: 12.70351 | G17: Brand Engagement | H17: 226.30826
A18: #HealthTech | B18: 25 | D18: #Health | E18: 12.70351 | G18: Product Launch | H18: 193.71835
A19: #iPadPro | B19: 19 | D19: #AppleDesign | E19: 12.379917 | G19: Health & Fitness Awareness | H19: 177.86828
A20: #MacBookProM3 | B20: 17 | D20: #Innovation | E20: 12.379917 | G20: Sustainability Branding | H20: 149.4757
A21: #Sustainability | B21: 13 | D21: #iPadPro | E21: 12.343924 | G21: Product Promotion | H21: 131.03349
A22: #AppleEarth | B22: 13 | D22: #MacBookProM3 | E22: 11.890804 | G22: Image
G23: Health & Fitness Awareness | H23: 238.03198
G24: Brand Engagement | H24: 225.38957
G25: Product Launch | H25: 150.10063
G26: Product Promotion | H26: 140.72786
G27: Sustainability Branding | H27: 114.67608
A29: Content type performance | D29: Recommendation according to content type
A30: Row Labels | B30: Sum of performance
A31: Instagram | B31: 973.46736
A32: Carousel | B32: 307.15927
A33: Video | B33: 258.70251
A34: Image | B34: 207.5503
A35: Tweet | B35: 200.05528
A36: LinkedIn | B36: 1115.8003
A37: Image | B37: 323.23959
A38: Video | B38: 306.88187
A39: Carousel | B39: 245.01618
A40: Tweet | B40: 240.66269
A41: Twitter | B41: 1030.5142
A42: Carousel | B42: 402.94083
...

Sheet Campaign Effectiveness
A2: Total & Average Impressions, Likes, Clicks per Campaign.
A3: Row Labels | B3: Sum of Impressions | C3: Average of Impressions | D3: Sum of Likes | E3: Average of Likes | F3: Sum of Clicks | G3: Average of Clicks
A4: Apple Event September 2025 | B4: 10331022 | C4: 149724.96 | D4: 957050 | E4: 13870.29 | F4: 114854 | G4: 1664.5507
A5: Apple Watch Ultra 2 Launch | B5: 9407749 | C5: 136344.19 | D5: 888529 | E5: 12877.232 | F5: 106775 | G5: 1547.4638
A6: iPhone 16 Launch | B6: 8901334 | C6: 150870.07 | D6: 843431 | E6: 14295.441 | F6: 96543 | G6: 1636.322
A7: MacBook Air M3 Campaign | B7: 6698763 | C7: 145625.28 | D7: 585970 | E7: 12738.478 | F7: 74667 | G7: 1623.1957
A8: Sustainability Awareness Drive | B8: 9222999 | C8: 161807 | D8: 792463 | E8: 13902.86 | F8: 89166 | G8: 1564.3158
A9: Grand Total | B9: 44561867 | C9: 148539.56 | D9: 4067443 | E9: 13558.143 | F9: 482005 | G9: 1606.6833
A12: Engagement Uplift
A13: Campaign_Name | B13: Start_Date | C13: End_Date | D13: Campaign Duration | E13: Before Date | F13: Engagement During | G13: Engagement Before | H13: Daily Engagement During | I13: Daily Engagement Before | J13: Engagement Uplift
A14: iPhone 16 Launch | B14: 45458 | C14: 45488 | D14: =(C14-B14)+1 -> 31 | E14: =B14-D14 -> 45427 | F14: =SUMIFS(Likes,Date,">="&'Campaign Effectiveness'!B14,Date,"<="&'Campaign Effectiveness'!C14)+SUMIFS(Comments,Date,">="&'Campaign Effectiveness'!B14,Date,"<="&'Campaign Effectiveness'!C14)+SUMIFS(Shares,Date,">="&'Campaign Effectiveness'!B14,Date,"<="&'Campaign Effectiveness'!C14) -> 331108 | G14: =SUMIFS(Likes,Date,">="&'Campaign Effectiveness'!E14,Date,"<="&'Campaign Effectiveness'!B14)+SUMIFS(Comments,Date,">="&'Campaign Effectiveness'!E14,Date,"<="&'Campaign Effectiveness'!B14)+SUMIFS(Shares,Date,">="&'Campaign Effectiveness'!E14,Date,"<="&'Campaign Effectiveness'!B14) -> 236231 | H14: =F14/D14 -> 10680.903 | I14: =G14/D14 -> 7620.3548 | J14: =(H14-I14)/H14 -> 0.28654397
A15: MacBook Air M3 Campaign | B15: 45566 | C15: 45596 | D15: =(C15-B15)+1 -> 31 | E15: =B15-D15 -> 45535 | F15: =SUMIFS(Likes,Date,">="&'Campaign Effectiveness'!B15,Date,"<="&'Campaign Effectiveness'!C15)+SUMIFS(Comments,Date,">="&'Campaign Effectiveness'!B15,Date,"<="&'Campaign Effectiveness'!C15)+SUMIFS(Shares,Date,">="&'Campaign Effectiveness'!B15,Date,"<="&'Campaign Effectiveness'!C15) -> 409967 | G15: =SUMIFS(Likes,Date,">="&'Campaign Effectiveness'!E15,Date,"<="&'Campaign Effectiveness'!B15)+SUMIFS(Comments,Date,">="&'Campaign Effectiveness'!E15,Date,"<="&'Campaign Effectiveness'!B15)+SUMIFS(Shares,Date,">="&'Campaign Effectiveness'!E15,Date,"<="&'Campaign Effectiveness'!B15) -> 127344 | H15: =F15/D15 -> 13224.742 | I15: =G15/D15 -> 4107.871 | J15: =(H15-I15)/H15 -> 0.68937988
A16: Apple Watch Ultra 2 Launch | B16: 45651 | C16: 45667 | D16: =(C16-B16)+1 -> 17 | E16: =B16-D16 -> 45634 | F16: =SUMIFS(Likes,Date,">="&'Campaign Effectiveness'!B16,Date,"<="&'Campaign Effectiveness'!C16)+SUMIFS(Comments,Date,">="&'Campaign Effectiveness'!B16,Date,"<="&'Campaign Effectiveness'!C16)+SUMIFS(Shares,Date,">="&'Campaign Effectiveness'!B16,Date,"<="&'Campaign Effectiveness'!C16) -> 88599 | G16: =SUMIFS(Likes,Date,">="&'Campaign Effectiveness'!E16,Date,"<="&'Campaign Effectiveness'!B16)+SUMIFS(Comments,Date,">="&'Campaign Effectiveness'!E16,Date,"<="&'Campaign Effectiveness'!B16)+SUMIFS(Shares,Date,">="&'Campaign Effectiveness'!E16,Date,"<="&'Campaign Effectiveness'!B16) -> 197099 | H16: =F16/D16 -> 5211.7059 | I16: =G16/D16 -> 11594.059 | J16: =(H16-I16)/H16 -> -1.2246188
A17: Sustainability Awareness Drive | B17: 45717 | C17: 45747 | D17: =(C17-B17)+1 -> 31 | E17: =B17-D17 -> 45686 | F17: =SUMIFS(Likes,Date,">="&'Campaign Effectiveness'!B17,Date,"<="&'Campaign Effectiveness'!C17)+SUMIFS(Comments,Date,">="&'Campaign Effectiveness'!B17,Date,"<="&'Campaign Effectiveness'!C17)+SUMIFS(Shares,Date,">="&'Campaign Effectiveness'!B17,Date,"<="&'Campaign Effectiveness'!C17) -> 370695 | G17: =SUMIFS(Likes,Date,">="&'Campaign Effectiveness'!E17,Date,"<="&'Campaign Effectiveness'!B17)+SUMIFS(Comments,Date,">="&'Campaign Effectiveness'!E17,Date,"<="&'Campaign Effectiveness'!B17)+SUMIFS(Shares,Date,">="&'Campaign Effectiveness'!E17,Date,"<="&'Campaign Effectiveness'!B17) -> 274312 | H17: =F17/D17 -> 11957.903 | I17: =G17/D17 -> 8848.7742 | J17: =(H17-I17)/H17 -> 0.2600062
A18: Apple Event September 2025 | B18: 45901 | C18: 45930 | D18: =(C18-B18)+1 -> 30 | E18: =B18-D18 -> 45871 | F18: =SUMIFS(Likes,Date,">="&'Campaign Effectiveness'!B18,Date,"<="&'Campaign Effectiveness'!C18)+SUMIFS(Comments,Date,">="&'Campaign Effectiveness'!B18,Date,"<="&'Campaign Effectiveness'!C18)+SUMIFS(Shares,Date,">="&'Campaign Effectiveness'!B18,Date,"<="&'Campaign Effectiveness'!C18) -> 826669 | G18: =SUMIFS(Likes,Date,">="&'Campaign Effectiveness'!E18,Date,"<="&'Campaign Effectiveness'!B18)+SUMIFS(Comments,Date,">="&'Campaign Effectiveness'!E18,Date,"<="&'Campaign Effectiveness'!B18)+SUMIFS(Shares,Date,">="&'Campaign Effectiveness'!E18,Date,"<="&'Campaign Effectiveness'!B18) -> 0 | H18: =F18/D18 -> 27555.633 | I18: =G18/D18 -> 0 | J18: =(H18-I18)/H18 -> 1
A22: Pivot Table to Calculate Engagement per Campaign
A23: Row Labels | B23: Engagement(Campaign)
A24: Apple Event September 2025 | B24: 1051098
A25: Apple Watch Ultra 2 Launch | B25: 991433
A26: iPhone 16 Launch | B26: 926462
A27: MacBook Air M3 Campaign | B27: 652233
A28: Sustainability Awareness Drive | B28: 879891
A30: Campaign with Highest ROI
A31: Campaign_Name | B31: Ad_Spend | C31: Engagement | D31: ROI
A32: Apple Watch Ultra 2 Launch | B32: 55000 | C32: 926462 | D32: =C32/B32 -> 16.844764
A33: MacBook Air M3 Campaign | B33: 60000 | C33: 991433 | D33: =C33/B33 -> 16.523883
A34: Sustainability Awareness Drive | B34: 40000 | C34: 652233 | D34: =C34/B34 -> 16.305825
A35: iPhone 16 Launch | B35: 85000 | C35: 1051098 | D35: =C35/B35 -> 12.365859
A36: Apple Event September 2025 | B36: 75000 | C36: 879891 | D36: =C36/B36 -> 11.73188
A39: Campaign with Highest Follower Gain
A40: Campaign_Name | B40: Follower Gain
A41: Sustainability Awareness Drive | B41: 107259
A42: iPhone 16 Launch | B42: 106800
A43: MacBook Air M3 Campaign | B43: 99093
A44: Apple Watch Ultra 2 Launch | B44: 50927
A45: Apple Event September 2025 | B45: 0

Sheet Follower Retention
A1: Weekly follower growth per platform
A2: Sum of Follower Gain
B3: Instagram | C3: LinkedIn | D3: Twitter | E3: YouTube
A4: 2024 | B4: 184130 | C4: 154042 | D4: 176448 | E4: 157994
A5: 03-Jun | B5: 3777 | C5: 0 | D5: 7432 | E5: 15994
A6: 10-Jun | B6: 7215 | C6: 0 | D6: 8369 | E6: 7478
A7: 17-Jun | B7: 13130 | C7: 6728 | D7: 6073 | E7: 0
A8: 24-Jun | B8: 4885 | C8: 0 | D8: 15084 | E8: 8653
A9: 01-Jul | B9: 5928 | C9: 5442 | D9: 8463 | E9: 0
A10: 08-Jul | B10: 0 | C10: 11378 | D10: 7151 | E10: 0
A11: 15-Jul | B11: 4967 | C11: 0 | D11: 7092 | E11: 1826
A12: 22-Jul | B12: 0 | C12: 15403 | D12: 7733 | E12: 9082
A13: 29-Jul | B13: 0 | C13: 7537 | D13: 6039 | E13: 3445
A14: 05-Aug | B14: 3213 | C14: 4847 | D14: 3497 | E14: 2543
A15: 12-Aug | B15: 6853 | C15: 0 | D15: 12800 | E15: 7033
... A55: 12-May | B55: 2805 | C55: 8146 | D55: 7436 | E55: 0

Sheet Correlation
A1: Ad_Spend | B1: Follower Gain
A2: 23944 | B2: 3777
A3: 29873 | B3: 7432
A4: 50372 | B4: 8123
A5: 33928 | B5: 7871
A6: 25379 | B6: 7215
A7: 46751 | B7: 7478
A8: 44546 | B8: 4934
A9: 34286 | B9: 3435
A10: 15110 | B10: 7452
A11: 22087 | B11: 6073
A12: 33762 | B12: 6728
A13: 27081 | B13: 5678
... A201: 41703 | B201: 7436

Sheet Video links
A1: https://drive.google.com/file/d/10Dxd6bVoLQNcY_ndxcAPbrI0I7FdMB1G/view?usp=sharing
